<?xml version="1.0"?>
<sdf version="1.6">
	<world name="ros_ign_tutorial">

		<physics name="1ms" type="ignored">
			<max_step_size>0.001</max_step_size>
			<real_time_factor>1.0</real_time_factor>
		</physics>
		<plugin filename="ignition-gazebo-physics-system" name="ignition::gazebo::systems::Physics"></plugin>
		<plugin filename="ignition-gazebo-user-commands-system" name="ignition::gazebo::systems::UserCommands"></plugin>
		<plugin filename="ignition-gazebo-scene-broadcaster-system" name="ignition::gazebo::systems::SceneBroadcaster"></plugin>
		<plugin filename="ignition-gazebo-sensors-system" name="ignition::gazebo::systems::Sensors">
			<render_engine>ogre2</render_engine>
		</plugin>

		<gui fullscreen="0">

			<!-- 3D scene -->
			<plugin filename="GzScene3D" name="3D View">
				<ignition-gui>
					<title>3D View</title>
					<property type="bool" key="showTitleBar">false</property>
					<property type="string" key="state">docked</property>
				</ignition-gui>

				<engine>ogre2</engine>
				<scene>scene</scene>
				<ambient_light>0.4 0.4 0.4</ambient_light>
				<background_color>0.8 0.8 0.8</background_color>
				<camera_pose>-6 0 6 0 0.5 0</camera_pose>
			</plugin>

			<!-- Play / pause / step -->
			<plugin filename="WorldControl" name="World control">
				<ignition-gui>
					<title>World control</title>
					<property type="bool" key="showTitleBar">false</property>
					<property type="bool" key="resizable">false</property>
					<property type="double" key="height">72</property>
					<property type="double" key="width">121</property>
					<property type="double" key="z">1</property>

					<property type="string" key="state">floating</property>
					<anchors target="3D View">
						<line own="left" target="left" />
						<line own="bottom" target="bottom" />
					</anchors>
				</ignition-gui>

				<play_pause>true</play_pause>
				<step>true</step>
				<start_paused>true</start_paused>

			</plugin>

			<!-- Time / RTF -->
			<plugin filename="WorldStats" name="World stats">
				<ignition-gui>
					<title>World stats</title>
					<property type="bool" key="showTitleBar">false</property>
					<property type="bool" key="resizable">false</property>
					<property type="double" key="height">110</property>
					<property type="double" key="width">290</property>
					<property type="double" key="z">1</property>

					<property type="string" key="state">floating</property>
					<anchors target="3D View">
						<line own="right" target="right" />
						<line own="bottom" target="bottom" />
					</anchors>
				</ignition-gui>

				<sim_time>true</sim_time>
				<real_time>true</real_time>
				<real_time_factor>true</real_time_factor>
				<iterations>true</iterations>

			</plugin>

			<plugin filename="ImageDisplay" name="Image Display">
				<ignition-gui>
					<property key="state" type="string">docked</property>
				</ignition-gui>
			</plugin>
		</gui>

		<light type="directional" name="sun">
			<cast_shadows>true</cast_shadows>
			<pose>0 0 10 0 0 0</pose>
			<diffuse>1 1 1 1</diffuse>
			<specular>0.5 0.5 0.5 1</specular>
			<attenuation>
				<range>1000</range>
				<constant>0.9</constant>
				<linear>0.01</linear>
				<quadratic>0.001</quadratic>
			</attenuation>
			<direction>-0.5 0.1 -0.9</direction>
		</light>

		<model name="ground_plane">
			<static>true</static>
			<link name="link">
				<collision name="collision">
					<geometry>
						<plane>
							<normal>0 0 1</normal>
						</plane>
					</geometry>
				</collision>
				<visual name="visual">
					<geometry>
						<plane>
							<normal>0 0 1</normal>
							<size>100 100</size>
						</plane>
					</geometry>
					<material>
						<ambient>0.8 0.8 0.8 1</ambient>
						<diffuse>0.8 0.8 0.8 1</diffuse>
						<specular>0.8 0.8 0.8 1</specular>
					</material>
				</visual>
			</link>
		</model>

		<model name='vehicle'>
			<pose>0 0 0.325 0 -0 0</pose>

			<link name='chassis'>
				<pose>-0.151427 -0 0.175 0 -0 0</pose>
				<inertial>
					<mass>1.14395</mass>
					<inertia>
						<ixx>0.126164</ixx>
						<ixy>0</ixy>
						<ixz>0</ixz>
						<iyy>0.416519</iyy>
						<iyz>0</iyz>
						<izz>0.481014</izz>
					</inertia>
				</inertial>
				<visual name='visual'>
					<geometry>
						<box>
							<size>2.01142 1 0.568726</size>
						</box>
					</geometry>
					<material>
						<ambient>0.5 0.5 0.5 1</ambient>
						<diffuse>0.5 0.5 0.5 1</diffuse>
						<specular>0.5 0.5 0.5 1</specular>
					</material>
				</visual>
				<collision name='collision'>
					<geometry>
						<box>
							<size>2.01142 1 0.568726</size>
						</box>
					</geometry>
				</collision>
			</link>

			<link name='left_wheel'>
				<pose>0.554283 0.625029 -0.025 -1.5707 0 0</pose>
				<inertial>
					<mass>2</mass>
					<inertia>
						<ixx>0.145833</ixx>
						<ixy>0</ixy>
						<ixz>0</ixz>
						<iyy>0.145833</iyy>
						<iyz>0</iyz>
						<izz>0.125</izz>
					</inertia>
				</inertial>
				<visual name='visual'>
					<geometry>
						<sphere>
							<radius>0.3</radius>
						</sphere>
					</geometry>
					<material>
						<ambient>0.2 0.2 0.2 1</ambient>
						<diffuse>0.2 0.2 0.2 1</diffuse>
						<specular>0.2 0.2 0.2 1</specular>
					</material>
				</visual>
				<collision name='collision'>
					<geometry>
						<sphere>
							<radius>0.3</radius>
						</sphere>
					</geometry>
				</collision>
			</link>

			<link name='right_wheel'>
				<pose>0.554282 -0.625029 -0.025 -1.5707 0 0</pose>
				<inertial>
					<mass>2</mass>
					<inertia>
						<ixx>0.145833</ixx>
						<ixy>0</ixy>
						<ixz>0</ixz>
						<iyy>0.145833</iyy>
						<iyz>0</iyz>
						<izz>0.125</izz>
					</inertia>
				</inertial>
				<visual name='visual'>
					<geometry>
						<sphere>
							<radius>0.3</radius>
						</sphere>
					</geometry>
					<material>
						<ambient>0.2 0.2 0.2 1</ambient>
						<diffuse>0.2 0.2 0.2 1</diffuse>
						<specular>0.2 0.2 0.2 1</specular>
					</material>
				</visual>
				<collision name='collision'>
					<geometry>
						<sphere>
							<radius>0.3</radius>
						</sphere>
					</geometry>
				</collision>
			</link>

			<link name='caster'>
				<pose>-0.957138 -0 -0.125 0 -0 0</pose>
				<inertial>
					<mass>1</mass>
					<inertia>
						<ixx>0.1</ixx>
						<ixy>0</ixy>
						<ixz>0</ixz>
						<iyy>0.1</iyy>
						<iyz>0</iyz>
						<izz>0.1</izz>
					</inertia>
				</inertial>
				<visual name='visual'>
					<geometry>
						<sphere>
							<radius>0.2</radius>
						</sphere>
					</geometry>
					<material>
						<ambient>0.2 0.2 0.2 1</ambient>
						<diffuse>0.2 0.2 0.2 1</diffuse>
						<specular>0.2 0.2 0.2 1</specular>
					</material>
				</visual>
				<collision name='collision'>
					<geometry>
						<sphere>
							<radius>0.2</radius>
						</sphere>
					</geometry>
				</collision>
			</link>

			<link name="camera">
				<pose>0.85 0 0.25 0 0 0</pose>
				<inertial>
					<mass>0.1</mass>
					<inertia>
						<ixx>0.000166667</ixx>
						<iyy>0.000166667</iyy>
						<izz>0.000166667</izz>
					</inertia>
				</inertial>
				<collision name="collision">
					<geometry>
						<box>
							<size>0.1 0.1 0.1</size>
						</box>
					</geometry>
				</collision>
				<visual name="visual">
					<geometry>
						<box>
							<size>0.1 0.1 0.1</size>
						</box>
					</geometry>
					<material>
						<ambient>0.2 0.2 0.2 1</ambient>
						<diffuse>0.2 0.2 0.2 1</diffuse>
						<specular>0.2 0.2 0.2 1</specular>
					</material>
				</visual>
				<sensor name="camera" type="camera">
					<camera>
						<horizontal_fov>1.047</horizontal_fov>
						<image>
							<width>320</width>
							<height>240</height>
						</image>
						<clip>
							<near>0.1</near>
							<far>100</far>
						</clip>
					</camera>
					<always_on>1</always_on>
					<update_rate>30</update_rate>
					<visualize>true</visualize>
					<topic>camera</topic>
				</sensor>
			</link>

			<joint name='left_wheel_joint' type='revolute'>
				<parent>chassis</parent>
				<child>left_wheel</child>
				<axis>
					<xyz>0 0 1</xyz>
					<limit>
						<lower>-1.79769e+308</lower>
						<upper>1.79769e+308</upper>
					</limit>
				</axis>
			</joint>

			<joint name='right_wheel_joint' type='revolute'>
				<parent>chassis</parent>
				<child>right_wheel</child>
				<axis>
					<xyz>0 0 1</xyz>
					<limit>
						<lower>-1.79769e+308</lower>
						<upper>1.79769e+308</upper>
					</limit>
				</axis>
			</joint>

			<joint name='caster_wheel' type='ball'>
				<parent>chassis</parent>
				<child>caster</child>
			</joint>

			<joint name='camera_joint' type='fixed'>
				<parent>chassis</parent>
				<child>camera</child>
			</joint>

			<plugin filename="ignition-gazebo-diff-drive-system" name="ignition::gazebo::systems::DiffDrive">
				<left_joint>left_wheel_joint</left_joint>
				<right_joint>right_wheel_joint</right_joint>
				<wheel_separation>1.25</wheel_separation>
				<wheel_radius>0.3</wheel_radius>
				<odom_publish_frequency>1</odom_publish_frequency>
			</plugin>
			
		</model>

		

    <model name="sphere">
      <pose>3 3 1 0 0 0</pose>
      <link name="sphere_link">
        <collision name="sphere_collision">
          <geometry>
            <sphere>
              <radius>0.5</radius>
            </sphere>
          </geometry>
        </collision>
        <visual name="sphere_visual">
          <geometry>
            <sphere>
              <radius>0.5</radius>
            </sphere>
          </geometry>
          <material>
            <ambient>0.137 0.196 0.31 1</ambient>
            <diffuse>0.137 0.196 0.31 1</diffuse>
            <specular>0.137 0.196 0.31 1</specular>
          </material>
        </visual>
      </link>
    </model>

    <model name="camera">
			<static>true</static>
      <pose>0 0 20.0 0 1.57 0</pose>
      <link name="link">
        <pose>0.05 0.05 0.05 0 0 0</pose>
        <inertial>
          <mass>0.1</mass>
          <inertia>
            <ixx>0.000166667</ixx>
            <iyy>0.000166667</iyy>
            <izz>0.000166667</izz>
          </inertia>
        </inertial>
        <collision name="collision">
          <geometry>
            <box>
              <size>0.1 0.1 0.1</size>
            </box>
          </geometry>
        </collision>
        <visual name="visual">
          <geometry>
            <box>
              <size>0.1 0.1 0.1</size>
            </box>
          </geometry>
        </visual>
        <sensor name="camera" type="camera">
          <camera>
            <horizontal_fov>1.047</horizontal_fov>
            <image>
              <width>320</width>
              <height>240</height>
            </image>
            <clip>
              <near>0.1</near>
              <far>100</far>
            </clip>
          </camera>
          <always_on>1</always_on>
          <update_rate>30</update_rate>
          <visualize>true</visualize>
          <topic>camera2</topic>
        </sensor>
      </link>
    </model>


		<include>
			<pose>5 0 0 0 0 0</pose>
			<uri>
			https://fuel.ignitionrobotics.org/1.0/OpenRobotics/models/Construction Cone
			</uri>
		</include>

	</world>
</sdf>